Workbook

Sheet 使い方
A1: １．Loto7シート、Loto6シートに最新の抽選番号を反映する
A2: ２．Bシートに東京都千代田区の抽選当日の気象予報から、気温、気圧、湿度を入れる。 | J2: サイト
A3: ３．月齢とmoon_sin,moon_cosは1か月分を計算して事前に入れておく。 | J3: moon_age.py → moon_age_20260401_20260430.csv
A4: ４．Loto6とLoto7のシートのデータをすべて選択して新しいExcelに貼り付け、名前を付けて保存で、CSV形式に保存する
A5: ５．loto6_struct_map,loto7_struct_mapの下のCSVを全て削除する
A6: ６．lotoX_struct_map.py → lotoX_clusteperios.py → LotoX_pair_sync.py →
A7: LotoX_cluster_env.py → LotoX_compute_sync_network_score.py → LotoX_period.py の順番に実行する
A8: ７．LotoXV6.pyにBシートから予測したい日の気象条件を記入する
A9: ８．LotoXV6.pyを実行して、予測結果を表示する。
A11: コマンドプロンプトで下記ディレクトリに移動して、py.exeで実行しても動く。
A12: C:\Users\yasu9\source\repos\Loto>
A14: C:\Users\yasu9\AppData\Local\Programs\Python\Launcher\py.exe -3.11 "C:\Users\yasu9\source\repos\Loto\lotoX_struct_map.py"
A15: C:\Users\yasu9\AppData\Local\Programs\Python\Launcher\py.exe -3.11 "C:\Users\yasu9\source\repos\Loto\lotoX_clusteperios.py"
A16: C:\Users\yasu9\AppData\Local\Programs\Python\Launcher\py.exe -3.11 "C:\Users\yasu9\source\repos\Loto\LotoX_pair_sync.py"
A17: C:\Users\yasu9\AppData\Local\Programs\Python\Launcher\py.exe -3.11 "C:\Users\yasu9\source\repos\Loto\LotoX_cluster_env.py"
... A21: C:\Users\yasu9\AppData\Local\Programs\Python\Launcher\py.exe -3.11 "C:\Users\yasu9\source\repos\Loto\LotoXV6.py"
A23: python.exe "loto6_struct_map.py" | G23: python.exe "Loto7_struct_map.py"
A24: python.exe "loto6_clusteperios.py" | G24: python.exe "Loto7_clusteperios.py"
A25: python.exe "Loto6_pair_sync.py" | G25: python.exe "Loto7_pair_sync.py"
A26: python.exe "Loto6_cluster_env.py" | G26: python.exe "Loto7_cluster_env.py"
A27: python.exe "Loto6_compute_sync_network_score.py" | G27: python.exe "Loto7_compute_sync_network_score.py"
A28: python.exe "Loto6_period.py" | G28: python.exe "Loto7_period.py"
A30: python.exe "Loto6V6.py" | G30: python.exe "Loto7V6.py"

Sheet Loto7
A1: date | B1: num1 | C1: num2 | D1: num3 | E1: num4 | F1: num5 | G1: num6 | H1: num7 | I1: num8 | J1: num9 | K1: temp | L1: temp_diff | M1: pressure | N1: pressure_diff | O1: humidity | P1: humidity_diff | Q1: moon_age | R1: moon_sin | S1: moon_cos
A2: 41369 | B2: 7 | C2: 10 | D2: 12 | E2: 17 | F2: 23 | G2: 28 | H2: 34 | I2: 3 | J2: 15 | K2: =VLOOKUP(A2, Bシート!A:B, 2, FALSE) -> 19.9 | L2: =VLOOKUP(A2, Bシート!A:C, 3, FALSE) -> 1.1 | M2: =VLOOKUP(A2, Bシート!A:D, 4, FALSE) -> 1012.5 | N2: =VLOOKUP(A2, Bシート!A:E, 5, FALSE) -> 1.8 | O2: =VLOOKUP(A2, Bシート!A:F, 6, FALSE) -> 61 | P2: =VLOOKUP(A2, Bシート!A:G, 7, FALSE) -> -1 | Q2: =VLOOKUP(A2, Bシート!A:H, 8, FALSE) -> 24.54 | R2: =VLOOKUP(A2, Bシート!A:I, 9, FALSE) -> -0.87 | S2: =VLOOKUP(A2, Bシート!A:J, 10, FALSE) -> 0.49
A3: 41376 | B3: 20 | C3: 24 | D3: 29 | E3: 31 | F3: 33 | G3: 34 | H3: 35 | I3: 12 | J3: 32 | K3: =VLOOKUP(A3, Bシート!A:B, 2, FALSE) -> 15.5 | L3: =VLOOKUP(A3, Bシート!A:C, 3, FALSE) -> 4.1 | M3: =VLOOKUP(A3, Bシート!A:D, 4, FALSE) -> 1003.6 | N3: =VLOOKUP(A3, Bシート!A:E, 5, FALSE) -> -2.9 | O3: =VLOOKUP(A3, Bシート!A:F, 6, FALSE) -> 39 | P3: =VLOOKUP(A3, Bシート!A:G, 7, FALSE) -> -23 | Q3: =VLOOKUP(A3, Bシート!A:H, 8, FALSE) -> 2 | R3: =VLOOKUP(A3, Bシート!A:I, 9, FALSE) -> 0.41 | S3: =VLOOKUP(A3, Bシート!A:J, 10, FALSE) -> 0.91
A4: 41383 | B4: 2 | C4: 7 | D4: 8 | E4: 11 | F4: 14 | G4: 23 | H4: 31 | I4: 5 | J4: 15 | K4: =VLOOKUP(A4, Bシート!A:B, 2, FALSE) -> 13.9 | L4: =VLOOKUP(A4, Bシート!A:C, 3, FALSE) -> -6.3 | M4: =VLOOKUP(A4, Bシート!A:D, 4, FALSE) -> 1007 | N4: =VLOOKUP(A4, Bシート!A:E, 5, FALSE) -> 9.7 | O4: =VLOOKUP(A4, Bシート!A:F, 6, FALSE) -> 22 | P4: =VLOOKUP(A4, Bシート!A:G, 7, FALSE) -> -54 | Q4: =VLOOKUP(A4, Bシート!A:H, 8, FALSE) -> 9 | R4: =VLOOKUP(A4, Bシート!A:I, 9, FALSE) -> 0.94 | S4: =VLOOKUP(A4, Bシート!A:J, 10, FALSE) -> -0.34
A5: 41390 | B5: 12 | C5: 13 | D5: 22 | E5: 23 | F5: 24 | G5: 28 | H5: 29 | I5: 2 | J5: 14 | K5: =VLOOKUP(A5, Bシート!A:B, 2, FALSE) -> 16.2 | L5: =VLOOKUP(A5, Bシート!A:C, 3, FALSE) -> -2.8 | M5: =VLOOKUP(A5, Bシート!A:D, 4, FALSE) -> 993.5 | N5: =VLOOKUP(A5, Bシート!A:E, 5, FALSE) -> -8.8 | O5: =VLOOKUP(A5, Bシート!A:F, 6, FALSE) -> 58 | P5: =VLOOKUP(A5, Bシート!A:G, 7, FALSE) -> 5 | Q5: =VLOOKUP(A5, Bシート!A:H, 8, FALSE) -> 16 | R5: =VLOOKUP(A5, Bシート!A:I, 9, FALSE) -> -0.26 | S5: =VLOOKUP(A5, Bシート!A:J, 10, FALSE) -> -0.97
A6: 41397 | B6: 1 | C6: 3 | D6: 4 | E6: 5 | F6: 16 | G6: 21 | H6: 28 | I6: 22 | J6: 31 | K6: =VLOOKUP(A6, Bシート!A:B, 2, FALSE) -> 16.5 | L6: =VLOOKUP(A6, Bシート!A:C, 3, FALSE) -> 0.4 | M6: =VLOOKUP(A6, Bシート!A:D, 4, FALSE) -> 1007.1 | N6: =VLOOKUP(A6, Bシート!A:E, 5, FALSE) -> 4.3 | O6: =VLOOKUP(A6, Bシート!A:F, 6, FALSE) -> 54 | P6: =VLOOKUP(A6, Bシート!A:G, 7, FALSE) -> 28 | Q6: =VLOOKUP(A6, Bシート!A:H, 8, FALSE) -> 23 | R6: =VLOOKUP(A6, Bシート!A:I, 9, FALSE) -> -0.98 | S6: =VLOOKUP(A6, Bシート!A:J, 10, FALSE) -> 0.18
A7: 41404 | B7: 5 | C7: 15 | D7: 19 | E7: 23 | F7: 30 | G7: 34 | H7: 35 | I7: 6 | J7: 25 | K7: =VLOOKUP(A7, Bシート!A:B, 2, FALSE) -> 24.3 | L7: =VLOOKUP(A7, Bシート!A:C, 3, FALSE) -> 2 | M7: =VLOOKUP(A7, Bシート!A:D, 4, FALSE) -> 1002.5 | N7: =VLOOKUP(A7, Bシート!A:E, 5, FALSE) -> -4.5 | O7: =VLOOKUP(A7, Bシート!A:F, 6, FALSE) -> 50 | P7: =VLOOKUP(A7, Bシート!A:G, 7, FALSE) -> -2 | Q7: =VLOOKUP(A7, Bシート!A:H, 8, FALSE) -> 0.47 | R7: =VLOOKUP(A7, Bシート!A:I, 9, FALSE) -> 0.1 | S7: =VLOOKUP(A7, Bシート!A:J, 10, FALSE) -> 0.99
A8: 41411 | B8: 1 | C8: 3 | D8: 5 | E8: 7 | F8: 27 | G8: 29 | H8: 33 | I8: 6 | J8: 15 | K8: =VLOOKUP(A8, Bシート!A:B, 2, FALSE) -> 19.7 | L8: =VLOOKUP(A8, Bシート!A:C, 3, FALSE) -> -0.3 | M8: =VLOOKUP(A8, Bシート!A:D, 4, FALSE) -> 1011.1 | N8: =VLOOKUP(A8, Bシート!A:E, 5, FALSE) -> 3.2 | O8: =VLOOKUP(A8, Bシート!A:F, 6, FALSE) -> 57 | P8: =VLOOKUP(A8, Bシート!A:G, 7, FALSE) -> -4 | Q8: =VLOOKUP(A8, Bシート!A:H, 8, FALSE) -> 7.47 | R8: =VLOOKUP(A8, Bシート!A:I, 9, FALSE) -> 1 | S8: =VLOOKUP(A8, Bシート!A:J, 10, FALSE) -> -0.02
A9: 41418 | B9: 2 | C9: 21 | D9: 28 | E9: 29 | F9: 30 | G9: 32 | H9: 36 | I9: 6 | J9: 8 | K9: =VLOOKUP(A9, Bシート!A:B, 2, FALSE) -> 24.1 | L9: =VLOOKUP(A9, Bシート!A:C, 3, FALSE) -> 2.4 | M9: =VLOOKUP(A9, Bシート!A:D, 4, FALSE) -> 1008.2 | N9: =VLOOKUP(A9, Bシート!A:E, 5, FALSE) -> 1.6 | O9: =VLOOKUP(A9, Bシート!A:F, 6, FALSE) -> 42 | P9: =VLOOKUP(A9, Bシート!A:G, 7, FALSE) -> -2 | Q9: =VLOOKUP(A9, Bシート!A:H, 8, FALSE) -> 14.47 | R9: =VLOOKUP(A9, Bシート!A:I, 9, FALSE) -> 0.06 | S9: =VLOOKUP(A9, Bシート!A:J, 10, FALSE) -> -1
A10: 41425 | B10: 3 | C10: 4 | D10: 15 | E10: 23 | F10: 27 | G10: 30 | H10: 36 | I10: 13 | J10: 35 | K10: =VLOOKUP(A10, Bシート!A:B, 2, FALSE) -> 24.8 | L10: =VLOOKUP(A10, Bシート!A:C, 3, FALSE) -> 2.8 | M10: =VLOOKUP(A10, Bシート!A:D, 4, FALSE) -> 1006.3 | N10: =VLOOKUP(A10, Bシート!A:E, 5, FALSE) -> 2 | O10: =VLOOKUP(A10, Bシート!A:F, 6, FALSE) -> 37 | P10: =VLOOKUP(A10, Bシート!A:G, 7, FALSE) -> -51 | Q10: =VLOOKUP(A10, Bシート!A:H, 8, FALSE) -> 21.47 | R10: =VLOOKUP(A10, Bシート!A:I, 9, FALSE) -> -0.99 | S10: =VLOOKUP(A10, Bシート!A:J, 10, FALSE) -> -0.14
A11: 41432 | B11: 1 | C11: 2 | D11: 3 | E11: 6 | F11: 24 | G11: 28 | H11: 30 | I11: 16 | J11: 20 | K11: =VLOOKUP(A11, Bシート!A:B, 2, FALSE) -> 23.4 | L11: =VLOOKUP(A11, Bシート!A:C, 3, FALSE) -> 0.4 | M11: =VLOOKUP(A11, Bシート!A:D, 4, FALSE) -> 1006.1 | N11: =VLOOKUP(A11, Bシート!A:E, 5, FALSE) -> -4.3 | O11: =VLOOKUP(A11, Bシート!A:F, 6, FALSE) -> 50 | P11: =VLOOKUP(A11, Bシート!A:G, 7, FALSE) -> -12 | Q11: =VLOOKUP(A11, Bシート!A:H, 8, FALSE) -> 28.47 | R11: =VLOOKUP(A11, Bシート!A:I, 9, FALSE) -> -0.22 | S11: =VLOOKUP(A11, Bシート!A:J, 10, FALSE) -> 0.97
A12: 41439 | B12: 9 | C12: 15 | D12: 26 | E12: 29 | F12: 32 | G12: 34 | H12: 36 | I12: 14 | J12: 35 | K12: =VLOOKUP(A12, Bシート!A:B, 2, FALSE) -> 26.7 | L12: =VLOOKUP(A12, Bシート!A:C, 3, FALSE) -> 5.4 | M12: =VLOOKUP(A12, Bシート!A:D, 4, FALSE) -> 1008.4 | N12: =VLOOKUP(A12, Bシート!A:E, 5, FALSE) -> -0.6 | O12: =VLOOKUP(A12, Bシート!A:F, 6, FALSE) -> 77 | P12: =VLOOKUP(A12, Bシート!A:G, 7, FALSE) -> -15 | Q12: =VLOOKUP(A12, Bシート!A:H, 8, FALSE) -> 5.94 | R12: =VLOOKUP(A12, Bシート!A:I, 9, FALSE) -> 0.95 | S12: =VLOOKUP(A12, Bシート!A:J, 10, FALSE) -> 0.3
A13: 41446 | B13: 11 | C13: 12 | D13: 14 | E13: 19 | F13: 26 | G13: 27 | H13: 33 | I13: 24 | J13: 32 | K13: =VLOOKUP(A13, Bシート!A:B, 2, FALSE) -> 22.3 | L13: =VLOOKUP(A13, Bシート!A:C, 3, FALSE) -> 0.5 | M13: =VLOOKUP(A13, Bシート!A:D, 4, FALSE) -> 1002 | N13: =VLOOKUP(A13, Bシート!A:E, 5, FALSE) -> -0.2 | O13: =VLOOKUP(A13, Bシート!A:F, 6, FALSE) -> 87 | P13: =VLOOKUP(A13, Bシート!A:G, 7, FALSE) -> -3 | Q13: =VLOOKUP(A13, Bシート!A:H, 8, FALSE) -> 12.94 | R13: =VLOOKUP(A13, Bシート!A:I, 9, FALSE) -> 0.38 | S13: =VLOOKUP(A13, Bシート!A:J, 10, FALSE) -> -0.93
... A626: 46150 | B626: 2 | C626: 6 | D626: 15 | E626: 19 | F626: 20 | G626: 22 | H626: 27 | I626: 31 | J626: 33 | K626: =VLOOKUP(A626, Bシート!A:B, 2, FALSE) -> 18.6 | L626: =VLOOKUP(A626, Bシート!A:C, 3, FALSE) -> -1.3 | M626: =VLOOKUP(A626, Bシート!A:D, 4, FALSE) -> 1023.3 | N626: =VLOOKUP(A626, Bシート!A:E, 5, FALSE) -> 12.8 | O626: =VLOOKUP(A626, Bシート!A:F, 6, FALSE) -> 52 | P626: =VLOOKUP(A626, Bシート!A:G, 7, FALSE) -> 16 | Q626: =VLOOKUP(A626, Bシート!A:H, 8, FALSE) -> 21.58 | R626: =VLOOKUP(A626, Bシート!A:I, 9, FALSE) -> -0.99 | S626: =VLOOKUP(A626, Bシート!A:J, 10, FALSE) -> -0.12

Sheet Bシート
A1: 年月日時 | B1: 気温(℃) | C1: 前日比 | D1: 現地気圧(hPa) | E1: 前日比 | F1: 湿度 | G1: 前日比 | H1: 月齢 | I1: moon_sin | J1: moon_cos
A2: 36800 | B2: 22.1 | D2: 1010.5 | F2: 61 | H2: 3.25 | I2: 0.64 | J2: 0.77
A3: 36801 | B3: 19.4 | C3: =B3-B2 -> -2.7 | D3: 1006.9 | E3: =D3-D2 -> -3.6 | F3: 79 | G3: =F3-F2 -> 18 | H3: 4.25 | I3: 0.79 | J3: 0.62
A4: 36802 | B4: 24 | C4: =B4-B3 -> 4.6 | D4: 1002.4 | E4: =D4-D3 -> -4.5 | F4: 70 | G4: =F4-F3 -> -9 | H4: 5.25 | I4: 0.9 | J4: 0.44
A5: 36803 | B5: 24.3 | C5: =B5-B4 -> 0.3 | D5: 1010.8 | E5: =D5-D4 -> 8.4 | F5: 58 | G5: =F5-F4 -> -12 | H5: 6.25 | I5: 0.97 | J5: 0.24
A6: 36804 | B6: 21.3 | C6: =B6-B5 -> -3 | D6: 1014.1 | E6: =D6-D5 -> 3.3 | F6: 65 | G6: =F6-F5 -> 7 | H6: 7.25 | I6: 1 | J6: 0.03
A7: 36805 | B7: 21.5 | C7: =B7-B6 -> 0.2 | D7: 1015.1 | E7: =D7-D6 -> 1 | F7: 55 | G7: =F7-F6 -> -10 | H7: 8.25 | I7: 0.98 | J7: -0.18
A8: 36806 | B8: 20.9 | C8: =B8-B7 -> -0.6 | D8: 1017.8 | E8: =D8-D7 -> 2.7 | F8: 44 | G8: =F8-F7 -> -11 | H8: 9.25 | I8: 0.92 | J8: -0.39
A9: 36807 | B9: 21.5 | C9: =B9-B8 -> 0.6 | D9: 1014.7 | E9: =D9-D8 -> -3.1 | F9: 57 | G9: =F9-F8 -> 13 | H9: 10.25 | I9: 0.82 | J9: -0.57
A10: 36808 | B10: 18.3 | C10: =B10-B9 -> -3.2 | D10: 1005.6 | E10: =D10-D9 -> -9.1 | F10: 86 | G10: =F10-F9 -> 29 | H10: 11.25 | I10: 0.68 | J10: -0.73
A11: 36809 | B11: 22.7 | C11: =B11-B10 -> 4.4 | D11: 1010.4 | E11: =D11-D10 -> 4.8 | F11: 63 | G11: =F11-F10 -> -23 | H11: 12.25 | I11: 0.51 | J11: -0.86
A12: 36810 | B12: 25.1 | C12: =B12-B11 -> 2.4 | D12: 1008.5 | E12: =D12-D11 -> -1.9 | F12: 65 | G12: =F12-F11 -> 2 | H12: 13.25 | I12: 0.32 | J12: -0.95
A13: 36811 | B13: 26.1 | C13: =B13-B12 -> 1 | D13: 1004.1 | E13: =D13-D12 -> -4.4 | F13: 56 | G13: =F13-F12 -> -9 | H13: 14.25 | I13: 0.11 | J13: -0.99
A14: 36812 | B14: 18.6 | C14: =B14-B13 -> -7.5 | D14: 1011.3 | E14: =D14-D13 -> 7.2 | F14: 62 | G14: =F14-F13 -> 6 | H14: 15.25 | I14: -0.1 | J14: -0.99
... A9359: 46157 | B9359: 20.8 | C9359: =B9359-B9358 -> -1.3 | D9359: 1022 | E9359: =D9359-D9358 -> 2.4 | F9359: 57 | G9359: =F9359-F9358 -> -8 | H9359: 28.58 | I9359: -0.2 | J9359: 0.98
A9360: 46158 | C9360: =B9360-B9359 -> -20.8 | E9360: =D9360-D9359 -> -1022 | G9360: =F9360-F9359 -> -57 | H9360: 0.05 | I9360: 0.01 | J9360: 1
A9361: 46159 | C9361: =B9361-B9360 -> 0 | E9361: =D9361-D9360 -> 0 | G9361: =F9361-F9360 -> 0 | H9361: 1.05 | I9361: 0.22 | J9361: 0.98
A9362: 46160 | C9362: =B9362-B9361 -> 0 | E9362: =D9362-D9361 -> 0 | G9362: =F9362-F9361 -> 0 | H9362: 2.05 | I9362: 0.42 | J9362: 0.91
A9363: 46161 | C9363: =B9363-B9362 -> 0 | E9363: =D9363-D9362 -> 0 | G9363: =F9363-F9362 -> 0 | H9363: 3.05 | I9363: 0.6 | J9363: 0.8
A9364: 46162 | C9364: =B9364-B9363 -> 0 | E9364: =D9364-D9363 -> 0 | G9364: =F9364-F9363 -> 0 | H9364: 4.05 | I9364: 0.76 | J9364: 0.65
A9365: 46163 | C9365: =B9365-B9364 -> 0 | E9365: =D9365-D9364 -> 0 | G9365: =F9365-F9364 -> 0 | H9365: 5.05 | I9365: 0.88 | J9365: 0.48
A9366: 46164 | C9366: =B9366-B9365 -> 0 | E9366: =D9366-D9365 -> 0 | G9366: =F9366-F9365 -> 0 | H9366: 6.05 | I9366: 0.96 | J9366: 0.28
A9367: 46165 | C9367: =B9367-B9366 -> 0 | E9367: =D9367-D9366 -> 0 | G9367: =F9367-F9366 -> 0 | H9367: 7.05 | I9367: 1 | J9367: 0.07
A9368: 46166 | C9368: =B9368-B9367 -> 0 | E9368: =D9368-D9367 -> 0 | G9368: =F9368-F9367 -> 0 | H9368: 8.05 | I9368: 0.99 | J9368: -0.14
A9369: 46167 | C9369: =B9369-B9368 -> 0 | E9369: =D9369-D9368 -> 0 | G9369: =F9369-F9368 -> 0 | H9369: 9.05 | I9369: 0.94 | J9369: -0.35
A9370: 46168 | C9370: =B9370-B9369 -> 0 | E9370: =D9370-D9369 -> 0 | G9370: =F9370-F9369 -> 0 | H9370: 10.05 | I9370: 0.84 | J9370: -0.54
A9371: 46169 | C9371: =B9371-B9370 -> 0 | E9371: =D9371-D9370 -> 0 | G9371: =F9371-F9370 -> 0 | H9371: 11.05 | I9371: 0.71 | J9371: -0.7
... A9375: 46173 | C9375: =B9375-B9374 -> 0 | E9375: =D9375-D9374 -> 0 | G9375: =F9375-F9374 -> 0 | H9375: 15.05 | I9375: -0.06 | J9375: -1

Sheet Loto6
A1: date | B1: num1 | C1: num2 | D1: num3 | E1: num4 | F1: num5 | G1: num6 | H1: num7 | I1: temp | J1: temp_diff | K1: pressure | L1: pressure_diff | M1: humidity | N1: humidity_diff | O1: moon_age | P1: moon_sin | Q1: moon_cos
A2: 36804 | B2: 2 | C2: 8 | D2: 10 | E2: 13 | F2: 27 | G2: 30 | H2: 39 | I2: =VLOOKUP(A2,Bシート!A:G,2,FALSE) -> 21.3 | J2: =VLOOKUP(A2,Bシート!A:G,3,FALSE) -> -3 | K2: =VLOOKUP(A2,Bシート!A:G,4,FALSE) -> 1014.1 | L2: =VLOOKUP(A2,Bシート!A:G,5,FALSE) -> 3.3 | M2: =VLOOKUP(A2,Bシート!A:G,6,FALSE) -> 65 | N2: =VLOOKUP(A2,Bシート!A:G,7,FALSE) -> 7 | O2: =VLOOKUP(A2,Bシート!A:H,8,FALSE) -> 7.25 | P2: =VLOOKUP(A2,Bシート!A:I,9,FALSE) -> 1 | Q2: =VLOOKUP(A2,Bシート!A:J,10,FALSE) -> 0.03
A3: 36811 | B3: 1 | C3: 9 | D3: 16 | E3: 20 | F3: 21 | G3: 43 | H3: 5 | I3: =VLOOKUP(A3,Bシート!A:G,2,FALSE) -> 26.1 | J3: =VLOOKUP(A3,Bシート!A:G,3,FALSE) -> 1 | K3: =VLOOKUP(A3,Bシート!A:G,4,FALSE) -> 1004.1 | L3: =VLOOKUP(A3,Bシート!A:G,5,FALSE) -> -4.4 | M3: =VLOOKUP(A3,Bシート!A:G,6,FALSE) -> 56 | N3: =VLOOKUP(A3,Bシート!A:G,7,FALSE) -> -9 | O3: =VLOOKUP(A3,Bシート!A:H,8,FALSE) -> 14.25 | P3: =VLOOKUP(A3,Bシート!A:I,9,FALSE) -> 0.11 | Q3: =VLOOKUP(A3,Bシート!A:J,10,FALSE) -> -0.99
A4: 36818 | B4: 1 | C4: 5 | D4: 15 | E4: 31 | F4: 36 | G4: 38 | H4: 13 | I4: =VLOOKUP(A4,Bシート!A:G,2,FALSE) -> 19.3 | J4: =VLOOKUP(A4,Bシート!A:G,3,FALSE) -> 1.6 | K4: =VLOOKUP(A4,Bシート!A:G,4,FALSE) -> 1018.8 | L4: =VLOOKUP(A4,Bシート!A:G,5,FALSE) -> 5.2 | M4: =VLOOKUP(A4,Bシート!A:G,6,FALSE) -> 63 | N4: =VLOOKUP(A4,Bシート!A:G,7,FALSE) -> 26 | O4: =VLOOKUP(A4,Bシート!A:H,8,FALSE) -> 21.25 | P4: =VLOOKUP(A4,Bシート!A:I,9,FALSE) -> -0.98 | Q4: =VLOOKUP(A4,Bシート!A:J,10,FALSE) -> -0.19
A5: 36825 | B5: 16 | C5: 18 | D5: 26 | E5: 27 | F5: 34 | G5: 40 | H5: 13 | I5: =VLOOKUP(A5,Bシート!A:G,2,FALSE) -> 21.8 | J5: =VLOOKUP(A5,Bシート!A:G,3,FALSE) -> 0.6 | K5: =VLOOKUP(A5,Bシート!A:G,4,FALSE) -> 1011.9 | L5: =VLOOKUP(A5,Bシート!A:G,5,FALSE) -> 4 | M5: =VLOOKUP(A5,Bシート!A:G,6,FALSE) -> 33 | N5: =VLOOKUP(A5,Bシート!A:G,7,FALSE) -> -49 | O5: =VLOOKUP(A5,Bシート!A:H,8,FALSE) -> 28.25 | P5: =VLOOKUP(A5,Bシート!A:I,9,FALSE) -> -0.27 | Q5: =VLOOKUP(A5,Bシート!A:J,10,FALSE) -> 0.96
A6: 36832 | B6: 9 | C6: 15 | D6: 21 | E6: 23 | F6: 27 | G6: 28 | H6: 43 | I6: =VLOOKUP(A6,Bシート!A:G,2,FALSE) -> 14.8 | J6: =VLOOKUP(A6,Bシート!A:G,3,FALSE) -> -0.2 | K6: =VLOOKUP(A6,Bシート!A:G,4,FALSE) -> 1010.1 | L6: =VLOOKUP(A6,Bシート!A:G,5,FALSE) -> -2.6 | M6: =VLOOKUP(A6,Bシート!A:G,6,FALSE) -> 90 | N6: =VLOOKUP(A6,Bシート!A:G,7,FALSE) -> 0 | O6: =VLOOKUP(A6,Bシート!A:H,8,FALSE) -> 5.72 | P6: =VLOOKUP(A6,Bシート!A:I,9,FALSE) -> 0.94 | Q6: =VLOOKUP(A6,Bシート!A:J,10,FALSE) -> 0.35
A7: 36839 | B7: 6 | C7: 12 | D7: 23 | E7: 25 | F7: 28 | G7: 38 | H7: 22 | I7: =VLOOKUP(A7,Bシート!A:G,2,FALSE) -> 12.9 | J7: =VLOOKUP(A7,Bシート!A:G,3,FALSE) -> -5.1 | K7: =VLOOKUP(A7,Bシート!A:G,4,FALSE) -> 1019.7 | L7: =VLOOKUP(A7,Bシート!A:G,5,FALSE) -> 6.7 | M7: =VLOOKUP(A7,Bシート!A:G,6,FALSE) -> 52 | N7: =VLOOKUP(A7,Bシート!A:G,7,FALSE) -> 15 | O7: =VLOOKUP(A7,Bシート!A:H,8,FALSE) -> 12.72 | P7: =VLOOKUP(A7,Bシート!A:I,9,FALSE) -> 0.42 | Q7: =VLOOKUP(A7,Bシート!A:J,10,FALSE) -> -0.91
A8: 36846 | B8: 7 | C8: 19 | D8: 21 | E8: 23 | F8: 33 | G8: 35 | H8: 26 | I8: =VLOOKUP(A8,Bシート!A:G,2,FALSE) -> 11.9 | J8: =VLOOKUP(A8,Bシート!A:G,3,FALSE) -> -4.5 | K8: =VLOOKUP(A8,Bシート!A:G,4,FALSE) -> 1022.8 | L8: =VLOOKUP(A8,Bシート!A:G,5,FALSE) -> 7.2 | M8: =VLOOKUP(A8,Bシート!A:G,6,FALSE) -> 63 | N8: =VLOOKUP(A8,Bシート!A:G,7,FALSE) -> -18 | O8: =VLOOKUP(A8,Bシート!A:H,8,FALSE) -> 19.72 | P8: =VLOOKUP(A8,Bシート!A:I,9,FALSE) -> -0.87 | Q8: =VLOOKUP(A8,Bシート!A:J,10,FALSE) -> -0.49
A9: 36853 | B9: 11 | C9: 16 | D9: 18 | E9: 20 | F9: 42 | G9: 43 | H9: 28 | I9: =VLOOKUP(A9,Bシート!A:G,2,FALSE) -> 11.9 | J9: =VLOOKUP(A9,Bシート!A:G,3,FALSE) -> 0.3 | K9: =VLOOKUP(A9,Bシート!A:G,4,FALSE) -> 1019.7 | L9: =VLOOKUP(A9,Bシート!A:G,5,FALSE) -> -3.4 | M9: =VLOOKUP(A9,Bシート!A:G,6,FALSE) -> 64 | N9: =VLOOKUP(A9,Bシート!A:G,7,FALSE) -> 16 | O9: =VLOOKUP(A9,Bシート!A:H,8,FALSE) -> 26.72 | P9: =VLOOKUP(A9,Bシート!A:I,9,FALSE) -> -0.56 | Q9: =VLOOKUP(A9,Bシート!A:J,10,FALSE) -> 0.83
A10: 36860 | B10: 11 | C10: 19 | D10: 23 | E10: 38 | F10: 39 | G10: 42 | H10: 15 | I10: =VLOOKUP(A10,Bシート!A:G,2,FALSE) -> 11.7 | J10: =VLOOKUP(A10,Bシート!A:G,3,FALSE) -> 2.1 | K10: =VLOOKUP(A10,Bシート!A:G,4,FALSE) -> 1016.4 | L10: =VLOOKUP(A10,Bシート!A:G,5,FALSE) -> -2 | M10: =VLOOKUP(A10,Bシート!A:G,6,FALSE) -> 37 | N10: =VLOOKUP(A10,Bシート!A:G,7,FALSE) -> -13 | O10: =VLOOKUP(A10,Bシート!A:H,8,FALSE) -> 4.19 | P10: =VLOOKUP(A10,Bシート!A:I,9,FALSE) -> 0.78 | Q10: =VLOOKUP(A10,Bシート!A:J,10,FALSE) -> 0.63
A11: 36867 | B11: 1 | C11: 3 | D11: 19 | E11: 21 | F11: 35 | G11: 39 | H11: 26 | I11: =VLOOKUP(A11,Bシート!A:G,2,FALSE) -> 8.5 | J11: =VLOOKUP(A11,Bシート!A:G,3,FALSE) -> -3.3 | K11: =VLOOKUP(A11,Bシート!A:G,4,FALSE) -> 1021.3 | L11: =VLOOKUP(A11,Bシート!A:G,5,FALSE) -> 10.2 | M11: =VLOOKUP(A11,Bシート!A:G,6,FALSE) -> 33 | N11: =VLOOKUP(A11,Bシート!A:G,7,FALSE) -> 2 | O11: =VLOOKUP(A11,Bシート!A:H,8,FALSE) -> 11.19 | P11: =VLOOKUP(A11,Bシート!A:I,9,FALSE) -> 0.69 | Q11: =VLOOKUP(A11,Bシート!A:J,10,FALSE) -> -0.72
A12: 36874 | B12: 12 | C12: 26 | D12: 32 | E12: 37 | F12: 40 | G12: 42 | H12: 16 | I12: =VLOOKUP(A12,Bシート!A:G,2,FALSE) -> 9 | J12: =VLOOKUP(A12,Bシート!A:G,3,FALSE) -> -1.6 | K12: =VLOOKUP(A12,Bシート!A:G,4,FALSE) -> 1015.7 | L12: =VLOOKUP(A12,Bシート!A:G,5,FALSE) -> 2 | M12: =VLOOKUP(A12,Bシート!A:G,6,FALSE) -> 49 | N12: =VLOOKUP(A12,Bシート!A:G,7,FALSE) -> 19 | O12: =VLOOKUP(A12,Bシート!A:H,8,FALSE) -> 18.19 | P12: =VLOOKUP(A12,Bシート!A:I,9,FALSE) -> -0.67 | Q12: =VLOOKUP(A12,Bシート!A:J,10,FALSE) -> -0.75
A13: 36881 | B13: 14 | C13: 17 | D13: 27 | E13: 28 | F13: 35 | G13: 39 | H13: 22 | I13: =VLOOKUP(A13,Bシート!A:G,2,FALSE) -> 11.6 | J13: =VLOOKUP(A13,Bシート!A:G,3,FALSE) -> 3.1 | K13: =VLOOKUP(A13,Bシート!A:G,4,FALSE) -> 1007.5 | L13: =VLOOKUP(A13,Bシート!A:G,5,FALSE) -> -5.1 | M13: =VLOOKUP(A13,Bシート!A:G,6,FALSE) -> 32 | N13: =VLOOKUP(A13,Bシート!A:G,7,FALSE) -> -46 | O13: =VLOOKUP(A13,Bシート!A:H,8,FALSE) -> 25.19 | P13: =VLOOKUP(A13,Bシート!A:I,9,FALSE) -> -0.8 | Q13: =VLOOKUP(A13,Bシート!A:J,10,FALSE) -> 0.6
... A2103: 46156 | B2103: 18 | C2103: 21 | D2103: 25 | E2103: 28 | F2103: 30 | G2103: 43 | H2103: 8 | I2103: =VLOOKUP(A2103,Bシート!A:G,2,FALSE) -> 22.1 | J2103: =VLOOKUP(A2103,Bシート!A:G,3,FALSE) -> 0.4 | K2103: =VLOOKUP(A2103,Bシート!A:G,4,FALSE) -> 1019.6 | L2103: =VLOOKUP(A2103,Bシート!A:G,5,FALSE) -> 1.8 | M2103: =VLOOKUP(A2103,Bシート!A:G,6,FALSE) -> 65 | N2103: =VLOOKUP(A2103,Bシート!A:G,7,FALSE) -> 9 | O2103: =VLOOKUP(A2103,Bシート!A:H,8,FALSE) -> 27.58 | P2103: =VLOOKUP(A2103,Bシート!A:I,9,FALSE) -> -0.4 | Q2103: =VLOOKUP(A2103,Bシート!A:J,10,FALSE) -> 0.92

Sheet Loto7予想
A1: 2 | B1: 8 | C1: 9 | D1: 15 | E1: 17 | F1: 21 | G1: 26 | H1: 29
A3: 2 | B3: 8 | C3: 9 | D3: 15 | E3: 17 | F3: 21 | G3: 26
A4: 2 | B4: 8 | C4: 9 | D4: 15 | E4: 17 | F4: 21 | H4: 29
A5: 2 | B5: 8 | C5: 9 | D5: 15 | E5: 17 | G5: 26 | H5: 29
A6: 2 | B6: 8 | C6: 9 | D6: 15 | F6: 21 | G6: 26 | H6: 29
A7: 2 | B7: 8 | C7: 9 | E7: 17 | F7: 21 | G7: 26 | H7: 29
A8: 2 | B8: 8 | D8: 15 | E8: 17 | F8: 21 | G8: 26 | H8: 29
A9: 2 | C9: 9 | D9: 15 | E9: 17 | F9: 21 | G9: 26 | H9: 29
B10: 8 | C10: 9 | D10: 15 | E10: 17 | F10: 21 | G10: 26 | H10: 29
A12: 1013hpの場合 | C12: 46080
A15: 8 | C15: 8 | D15: 8 | E15: 8 | F15: 8 | G15: 8 | H15: 8 | I15: 8
A16: 15 | C16: 15 | D16: 15 | E16: 15 | F16: 15 | G16: 15 | H16: 15 | J16: 15
A17: 16 | C17: 16 | D17: 16 | E17: 16 | F17: 16 | G17: 16 | I17: 16 | J17: 16
A18: 19 | C18: 19 | D18: 19 | E18: 19 | F18: 19 | H18: 19 | I18: 19 | J18: 19
A19: 22 | C19: 22 | D19: 22 | E19: 22 | G19: 22 | H19: 22 | I19: 22 | J19: 22
A20: 25 | C20: 25 | D20: 25 | F20: 25 | G20: 25 | H20: 25 | I20: 25 | J20: 25
A21: 29 | C21: 29 | E21: 29 | F21: 29 | G21: 29 | H21: 29 | I21: 29 | J21: 29
A22: 32 | D22: 32 | E22: 32 | F22: 32 | G22: 32 | H22: 32 | I22: 32 | J22: 32
A24: 29 | B24: 32 | C24: 15 | D24: 16 | E24: 25 | F24: 4 | G24: 3
A25: 1019hp | C25: 46094
A26: number | B26: proba_long | C26: proba_short | D26: final_score | G26: number | H26: proba_long | I26: proba_short | J26: final_score
A27: 0 | B27: 22 | C27: 0.691293 | D27: 0.197115 | E27: 0.444204 | G27: 0 | H27: 22 | I27: 0.691293 | J27: 0.199732 | K27: 0.467534 | M27: 8 | O27: 8 | P27: 8 | Q27: 8 | R27: 8 | S27: 8 | T27: 8 | U27: 8
A28: 1 | B28: 9 | C28: 0.620311 | D28: 0.211252 | E28: 0.415781 | G28: 1 | H28: 9 | I28: 0.620311 | J28: 0.172969 | K28: 0.416681 | M28: 9 | O28: 9 | P28: 9 | Q28: 9 | R28: 9 | S28: 9 | T28: 9 | V28: 9
A29: 2 | B29: 28 | C29: 0.280855 | D29: 0.203098 | E29: 0.241976 | G29: 2 | H29: 13 | I29: 0.286634 | J29: 0.184029 | K29: 0.239928 | M29: 13 | O29: 13 | P29: 13 | Q29: 13 | R29: 13 | S29: 13 | U29: 13 | V29: 13
A30: 3 | B30: 13 | C30: 0.286634 | D30: 0.182363 | E30: 0.234498 | G30: 3 | H30: 15 | I30: 0.301627 | J30: 0.156248 | K30: 0.23545 | M30: 14 | O30: 14 | P30: 14 | Q30: 14 | R30: 14 | T30: 14 | U30: 14 | V30: 14
A31: 4 | B31: 29 | C31: 0.188124 | D31: 0.244762 | E31: 0.216443 | G31: 4 | H31: 28 | I31: 0.280855 | J31: 0.141064 | K31: 0.217222 | M31: 15 | O31: 15 | P31: 15 | Q31: 15 | S31: 15 | T31: 15 | U31: 15 | V31: 15
A32: 5 | B32: 14 | C32: 0.220334 | D32: 0.192662 | E32: 0.206498 | G32: 5 | H32: 14 | I32: 0.220334 | J32: 0.203834 | K32: 0.212823 | M32: 22 | O32: 22 | P32: 22 | R32: 22 | S32: 22 | T32: 22 | U32: 22 | V32: 22
A33: 6 | B33: 8 | C33: 0.181217 | D33: 0.214914 | E33: 0.198065 | G33: 6 | H33: 29 | I33: 0.188124 | J33: 0.209151 | K33: 0.197696 | M33: 28 | O33: 28 | Q33: 28 | R33: 28 | S33: 28 | T33: 28 | U33: 28 | V33: 28
G34: 7 | H34: 8 | I34: 0.181217 | J34: 0.209099 | K34: 0.193909 | M34: 29 | P34: 29 | Q34: 29 | R34: 29 | S34: 29 | T34: 29 | U34: 29 | V34: 29
A35: Window=36,602
A36: weights: {'long': 0.35, 'short': 0.65}
B37: number | C37: proba_long | D37: proba_short | E37: final_score
A38: 0 | B38: 18 | C38: 0.844943 | D38: 0.340963 | E38: 0.517356 | G38: 8 | I38: 8 | J38: 8 | K38: 8 | L38: 8 | M38: 8 | N38: 8 | O38: 8
A39: 1 | B39: 22 | C39: 0.901945 | D39: 0.215215 | E39: 0.455571 | F39: 9 | G39: 9 | I39: 9 | J39: 9 | K39: 9 | L39: 9 | M39: 9 | N39: 9 | P39: 9
A40: 2 | B40: 29 | C40: 0.696711 | D40: 0.261379 | E40: 0.413745 | F40: 11 | G40: 11 | I40: 11 | J40: 11 | K40: 11 | L40: 11 | M40: 11 | O40: 11 | P40: 11
A41: 3 | B41: 14 | C41: 0.750674 | D41: 0.121836 | E41: 0.341929 | F41: 13 | G41: 14 | I41: 14 | J41: 14 | K41: 14 | L41: 14 | N41: 14 | O41: 14 | P41: 14
A42: 4 | B42: 23 | C42: 0.066042 | D42: 0.442168 | E42: 0.310524 | F42: 15 | G42: 18 | I42: 18 | J42: 18 | K42: 18 | M42: 18 | N42: 18 | O42: 18 | P42: 18
A43: 5 | B43: 11 | C43: 0.198495 | D43: 0.340963 | E43: 0.291099 | F43: 18 | G43: 22 | I43: 22 | J43: 22 | L43: 22 | M43: 22 | N43: 22 | O43: 22 | P43: 22
A44: 6 | B44: 9 | C44: 0.215407 | D44: 0.306674 | E44: 0.27473 | F44: 22 | G44: 23 | I44: 23 | K44: 23 | L44: 23 | M44: 23 | N44: 23 | O44: 23 | P44: 23
A45: 7 | B45: 8 | C45: 0.091197 | D45: 0.320208 | E45: 0.240055 | F45: 34 | G45: 29 | J45: 29 | K45: 29 | L45: 29 | M45: 29 | N45: 29 | O45: 29 | P45: 29
...

Sheet Loto6予想
A1: 46086
A2: 2 | C2: 2 | D2: 2 | E2: 2 | F2: 2 | G2: 2 | H2: 2 | M2: 18 | O2: 18 | P2: 18 | Q2: 18 | R2: 18 | S2: 18 | T2: 18
A3: 6 | C3: 6 | D3: 6 | E3: 6 | F3: 6 | G3: 6 | I3: 6 | M3: 24 | O3: 24 | P3: 24 | Q3: 24 | R3: 24 | S3: 24 | U3: 24
A4: 21 | C4: 21 | D4: 21 | E4: 21 | F4: 21 | H4: 21 | I4: 21 | M4: 26 | O4: 26 | P4: 26 | Q4: 26 | R4: 26 | T4: 26 | U4: 26
A5: 24 | C5: 24 | D5: 24 | E5: 24 | G5: 24 | H5: 24 | I5: 24 | M5: 29 | O5: 29 | P5: 29 | Q5: 29 | S5: 29 | T5: 29 | U5: 29
A6: 26 | C6: 26 | D6: 26 | F6: 26 | G6: 26 | H6: 26 | I6: 26 | M6: 35 | O6: 35 | P6: 35 | R6: 35 | S6: 35 | T6: 35 | U6: 35
A7: 35 | C7: 35 | E7: 35 | F7: 35 | G7: 35 | H7: 35 | I7: 35 | M7: 36 | O7: 36 | Q7: 36 | R7: 36 | S7: 36 | T7: 36 | U7: 36
A8: 42 | D8: 42 | E8: 42 | F8: 42 | G8: 42 | H8: 42 | I8: 42 | M8: 42 | P8: 42 | Q8: 42 | R8: 42 | S8: 42 | T8: 42 | U8: 42
A10: Window=810 | M10: Window=296
A11: number | B11: co_sum | C11: co_avg | D11: co_max | E11: co_6 | F11: co_37 | G11: co_42 | H11: co_2 | I11: co_38 | J11: proba | M11: number | N11: co_sum | O11: co_avg | P11: co_max | Q11: co_6 | R11: co_37 | S11: co_42 | T11: co_2 | U11: co_38 | V11: proba
A12: 23 | B12: 24 | C12: 1515 | D12: 35.232558 | E12: 45 | F12: 43 | G12: 41 | H12: 37 | I12: 42 | J12: 36 | K12: 0.165605 | M12: 25 | N12: 26 | O12: 1515 | P12: 35.232558 | Q12: 47 | R12: 30 | S12: 40 | T12: 42 | U12: 41 | V12: 33 | W12: 0.172528
A13: 1 | B13: 2 | C13: 1540 | D13: 35.813953 | E13: 48 | F13: 45 | G13: 38 | H13: 43 | I13: 0 | J13: 48 | K13: 0.163858 | M13: 17 | N13: 18 | O13: 1460 | P13: 33.953488 | Q13: 45 | R13: 45 | S13: 41 | T13: 30 | U13: 22 | V13: 40 | W13: 0.169966
A14: 41 | B14: 42 | C14: 1550 | D14: 36.046512 | E14: 47 | F14: 37 | G14: 36 | H14: 0 | I14: 43 | J14: 41 | K14: 0.162504 | M14: 34 | N14: 35 | O14: 1510 | P14: 35.116279 | Q14: 44 | R14: 36 | S14: 35 | T14: 44 | U14: 39 | V14: 34 | W14: 0.16952
A15: 25 | B15: 26 | C15: 1515 | D15: 35.232558 | E15: 47 | F15: 30 | G15: 40 | H15: 42 | I15: 41 | J15: 33 | K15: 0.15973 | M15: 35 | N15: 36 | O15: 1485 | P15: 34.534884 | Q15: 46 | R15: 40 | S15: 39 | T15: 34 | U15: 32 | V15: 35 | W15: 0.168704
A16: 34 | B16: 35 | C16: 1510 | D16: 35.116279 | E16: 44 | F16: 36 | G16: 35 | H16: 44 | I16: 39 | J16: 34 | K16: 0.156621 | M16: 23 | N16: 24 | O16: 1515 | P16: 35.232558 | Q16: 45 | R16: 43 | S16: 41 | T16: 37 | U16: 42 | V16: 36 | W16: 0.164228
A17: 20 | B17: 21 | C17: 1530 | D17: 35.581395 | E17: 47 | F17: 40 | G17: 38 | H17: 41 | I17: 38 | J17: 40 | K17: 0.156001 | M17: 41 | N17: 42 | O17: 1550 | P17: 36.046512 | Q17: 47 | R17: 37 | S17: 36 | T17: 0 | U17: 43 | V17: 41 | W17: 0.161765
A18: 5 | B18: 6 | C18: 1600 | D18: 37.209302 | E18: 48 | F18: 0 | G18: 41 | H18: 37 | I18: 45 | J18: 45 | K18: 0.155539 | M18: 28 | N18: 29 | O18: 1375 | P18: 31.976744 | Q18: 43 | R18: 27 | S18: 43 | T18: 33 | U18: 39 | V18: 27 | W18: 0.15776
A20: 3/9 ハイブリッド | C20: 1019hp
B21: 37 | C21: 0.174691 | D21: 0.397929 | E21: 0.241663 | G21: 6 | I21: 6 | J21: 6 | K21: 6 | L21: 6 | M21: 6 | N21: 6
B22: 12 | C22: 0.186872 | D22: 0.282455 | E22: 0.215547 | G22: 7 | I22: 7 | J22: 7 | K22: 7 | L22: 7 | M22: 7 | O22: 7
B23: 26 | C23: 0.18127 | D23: 0.261276 | E23: 0.205272 | G23: 10 | I23: 10 | J23: 10 | K23: 10 | L23: 10 | N23: 10 | O23: 10
B24: 7 | C24: 0.156941 | D24: 0.292304 | E24: 0.19755 | G24: 11 | I24: 11 | J24: 11 | K24: 11 | M24: 11 | N24: 11 | O24: 11
B25: 10 | C25: 0.178459 | D25: 0.237737 | E25: 0.196242 | G25: 12 | I25: 12 | J25: 12 | L25: 12 | M25: 12 | N25: 12 | O25: 12
B26: 11 | C26: 0.16658 | D26: 0.244174 | E26: 0.189858 | G26: 26 | I26: 26 | K26: 26 | L26: 26 | M26: 26 | N26: 26 | O26: 26
B27: 6 | C27: 0.155401 | D27: 0.261276 | E27: 0.187163 | G27: 37 | J27: 37 | K27: 37 | L27: 37 | M27: 37 | N27: 37 | O27: 37
A30: 3/12 moon版
A31: number | B31: score
A32: 42 | B32: 43 | C32: 0.189657 | E32: 22 | G32: 22 | H32: 22 | I32: 22 | J32: 22 | K32: 22 | L32: 22
A33: 23 | B33: 24 | C33: 0.185564 | E33: 24 | G33: 24 | H33: 24 | I33: 24 | J33: 24 | K33: 24 | M33: 24
A34: 25 | B34: 26 | C34: 0.171707 | E34: 26 | G34: 26 | H34: 26 | I34: 26 | J34: 26 | L34: 26 | M34: 26
A35: 29 | B35: 30 | C35: 0.167473 | E35: 30 | G35: 30 | H35: 30 | I35: 30 | K35: 30 | L35: 30 | M35: 30
A36: 41 | B36: 42 | C36: 0.160803 | E36: 35 | G36: 35 | H36: 35 | J36: 35 | K36: 35 | L36: 35 | M36: 35
A37: 34 | B37: 35 | C37: 0.158989 | E37: 42 | G37: 42 | I37: 42 | J37: 42 | K37: 42 | L37: 42 | M37: 42
A38: 21 | B38: 22 | C38: 0.155902 | E38: 43 | H38: 43 | I38: 43 | J38: 43 | K38: 43 | L38: 43 | M38: 43
A41: 3/19 重みづけ版
A42: (0 | B42: 35 | C42: 7 | E42: 5 | G42: 5 | H42: 5 | I42: 5 | J42: 5 | K42: 5 | L42: 5 | M42: 5
A43: 1 | B43: 19 | C43: 6 | E43: 8 | H43: 8 | I43: 8 | J43: 8 | K43: 8 | L43: 8 | M43: 8
A44: 2 | B44: 5 | C44: 5 | E44: 19 | G44: 19 | H44: 19 | I44: 19 | J44: 19 | K44: 19 | L44: 19 | M44: 19
A45: 3 | B45: 31 | C45: 4 | E45: 24 | G45: 24 | I45: 24 | J45: 24 | K45: 24 | L45: 24 | M45: 24
A46: 4 | B46: 36 | C46: 3 | E46: 31 | G46: 31 | H46: 31 | I46: 31 | J46: 31 | K46: 31 | L46: 31 | M46: 31
...
